# Nome: Ancient Ruins 
# Categoria: Ruínas 
# Tamanho: Médio 
# Autor: Desconhecido
# URL: n/a
# Convertido por: Vico

biomesToSpawnIn=plains,forest,taiga,taiga m,desert
uniqueMinDistance=4096
weight=1
embed_into_distance=0
preventRotation=0
acceptable_target_blocks=stone,grass,dirt,sand,gravel
unacceptable_target_blocks=flowing_water,water,flowing_lava,lava
dimensions=7,18,14
allowable_overhang=0
max_leveling=0
leveling_buffer=-1
preserve_water=1
preserve_lava=0
preserve_plants=1
random_height_offset=0,0


rule1=0,100,minecraft:coal_block
rule2=0,70,minecraft:stone_brick_stairs-2
rule3=0,75,minecraft:stone_brick_stairs
rule4=0,88,minecraft:stonebrick,minecraft:stonebrick-1,minecraft:stonebrick-2,minecraft:monster_egg-2,minecraft:monster_egg-3,minecraft:monster_egg-4
rule5=0,72,minecraft:stone_brick_stairs-1
rule6=0,100,teBlock;minecraft:mob_spawner;{SpawnCount:4,SpawnRange:5,Delay:20,MinSpawnDelay:300,MaxSpawnDelay:1200,RequiredPlayerRange:32,EntityId:Zombie,SpawnData:{id:Zombie,CustomName:Guarda,CustomNameVisible:1,PersistenceRequired:0b,Attributes:[{Name:"generic.maxHealth",Base:10},{Name:"generic.followRange",Base:20},{Name:"generic.knockbackResistance",Base:0.16f},{Name:"generic.movementSpeed",Base:0.5f}],IsBaby:0,CanBreakDoors:1,Equipment:[{id:"minecraft:diamond_sword",tag:{display:{Name:"Espada do Guarda"},ench:[{id:16,lvl:5}]},Count:1},{id:"minecraft:leather_boots",tag:{display:{color:2497308}}},{id:"minecraft:leather_leggings",tag:{display:{color:5525309}}},{Count:1,id:"minecraft:leather_chestplate",tag:{display:{color:4936480}}},{id:"minecraft:leather_helmet",tag:{display:{color:7048739}}}],DropChances:[0.08F,0F,0F,0.25F,0F]}}
rule4=0,88,minecraft:stonebrick,minecraft:stonebrick-1,minecraft:stonebrick-2,minecraft:monster_egg-2,minecraft:monster_egg-3,minecraft:monster_egg-4
rule8=0,73,minecraft:stone_brick_stairs-3
rule9=1,90,minecraft:fire
rule10=1,90,minecraft:fire
rule11=0,100,minecraft:iron_bars
rule12=0,100,minecraft:stone_slab-5
rule13=0,100,minecraft:lit_pumpkin
rule14=1,90,minecraft:fire
rule15=1,90,minecraft:fire
rule16=0,100,IInventory;IronChest:BlockIronChest;ChestGenHook:dungeonChest:16-3,IInventory;IronChest:BlockIronChest;ChestGenHook:bonusChest:40-3,IInventory;IronChest:BlockIronChest;ChestGenHook:bonusChest:40-3,IInventory;IronChest:BlockIronChest;ChestGenHook:strongholdCrossing:42-3
rule17=0,100,5-2
rule18=0,100,5
rule19=0,100,5-3


layer
0,0,0,0,0,0,0,0,0,0,0,0,0,0
1,3,3,3,3,3,3,3,3,3,3,3,1,0
8,4,4,4,4,4,4,4,4,4,4,4,2,0
8,4,4,4,4,4,4,4,4,4,4,4,2,0
8,4,4,4,4,4,4,4,4,4,4,4,2,0
8,4,4,4,7,4,4,4,4,4,4,4,2,0
8,4,4,4,4,4,4,4,4,4,4,4,2,0
8,4,4,4,4,4,4,4,4,4,4,4,2,0
8,4,4,4,4,4,4,4,4,4,4,4,2,0
8,4,4,4,4,4,6,4,4,4,4,4,2,0
8,4,4,4,4,4,4,4,4,4,4,4,2,0
8,4,4,4,4,4,4,4,4,4,4,4,2,0
8,4,4,4,4,4,4,4,4,4,4,4,2,0
8,4,4,4,4,4,4,4,4,4,4,4,2,0
8,4,4,4,4,4,4,4,4,4,4,4,2,0
8,4,4,4,4,4,4,4,4,4,4,4,2,0
8,4,4,4,4,4,4,4,4,4,4,4,2,0
1,5,5,5,5,5,5,5,5,5,5,5,1,0
endlayer

layer
0,0,0,0,0,0,0,0,0,0,0,0,0,0
14,0,0,0,0,0,0,0,0,0,0,0,9,0
0,4,11,4,0,0,0,0,0,4,11,4,0,0
0,11,0,0,0,0,0,0,0,0,0,11,0,0
0,4,12,12,12,0,0,0,12,12,12,4,0,0
0,11,12,13,12,0,0,0,12,13,12,11,0,0
0,4,12,12,12,0,0,0,12,12,12,4,0,0
0,0,0,0,0,0,0,0,0,0,0,0,0,0
0,0,0,0,0,0,0,0,0,0,0,0,0,0
0,0,0,0,0,0,0,0,0,0,0,0,0,0
0,0,0,0,0,0,0,0,0,0,0,0,0,0
0,0,0,0,0,0,0,0,0,0,0,0,0,0
0,4,12,12,12,0,0,0,12,12,12,4,0,0
0,11,12,13,12,0,0,0,12,13,12,11,0,0
0,4,12,12,12,0,0,0,12,12,12,4,0,0
0,11,0,0,0,0,0,0,0,0,0,11,0,0
0,4,11,4,0,0,0,0,0,4,11,4,0,0
15,0,0,0,0,0,0,0,0,0,0,0,10,0
endlayer

layer
0,0,0,0,0,0,0,0,0,0,0,0,0,0
0,0,0,0,0,0,0,0,0,0,0,0,0,0
0,4,11,4,0,0,0,0,0,4,11,4,0,0
0,11,0,0,0,0,0,0,0,0,0,11,0,0
0,4,0,0,0,0,0,0,0,0,0,4,0,0
0,11,0,18,0,0,0,0,0,16,0,11,0,0
0,4,0,0,0,0,0,0,0,0,0,4,0,0
0,0,0,0,0,0,0,0,0,0,0,0,0,0
0,0,0,0,0,0,0,0,0,0,0,0,0,0
0,0,0,0,0,0,0,0,0,0,0,0,0,0
0,0,0,0,0,0,0,0,0,0,0,0,0,0
0,0,0,0,0,0,0,0,0,0,0,0,0,0
0,4,0,0,0,0,0,0,0,0,0,4,0,0
0,11,0,19,0,0,0,0,0,17,0,11,0,0
0,4,0,0,0,0,0,0,0,0,0,4,0,0
0,11,0,0,0,0,0,0,0,0,0,11,0,0
0,4,11,4,0,0,0,0,0,4,11,4,0,0
0,0,0,0,0,0,0,0,0,0,0,0,0,0
endlayer

layer
0,0,0,0,0,0,0,0,0,0,0,0,0,0
0,0,0,0,0,0,0,0,0,0,0,0,0,0
0,4,11,4,0,0,0,0,0,4,11,4,0,0
0,11,0,0,0,0,0,0,0,0,0,11,0,0
0,4,0,0,0,0,0,0,0,0,0,4,0,0
0,11,0,0,0,0,0,0,0,0,0,11,0,0
0,4,0,0,0,0,0,0,0,0,0,4,0,0
0,0,0,0,0,0,0,0,0,0,0,0,0,0
0,0,0,0,0,0,0,0,0,0,0,0,0,0
0,0,0,0,0,0,0,0,0,0,0,0,0,0
0,0,0,0,0,0,0,0,0,0,0,0,0,0
0,0,0,0,0,0,0,0,0,0,0,0,0,0
0,4,0,0,0,0,0,0,0,0,0,4,0,0
0,11,0,0,0,0,0,0,0,0,0,11,0,0
0,4,0,0,0,0,0,0,0,0,0,4,0,0
0,11,0,0,0,0,0,0,0,0,0,11,0,0
0,4,11,4,0,0,0,0,0,4,11,4,0,0
0,0,0,0,0,0,0,0,0,0,0,0,0,0
endlayer

layer
0,0,0,0,0,0,0,0,0,0,0,0,0,0
0,0,0,0,0,0,0,0,0,0,0,0,0,0
0,4,4,4,4,0,0,0,4,4,4,4,0,0
0,4,0,0,0,0,0,0,0,0,0,4,0,0
0,4,0,0,0,0,0,0,0,0,0,4,0,0
0,4,0,0,0,0,0,0,0,0,0,4,0,0
0,4,0,0,0,0,0,0,0,0,0,4,0,0
0,4,0,0,0,0,0,0,0,0,0,4,0,0
0,0,0,0,0,0,0,0,0,0,0,0,0,0
0,0,0,0,0,0,0,0,0,0,0,0,0,0
0,0,0,0,0,0,0,0,0,0,0,0,0,0
0,4,0,0,0,0,0,0,0,0,0,4,0,0
0,4,0,0,0,0,0,0,0,0,0,4,0,0
0,4,0,0,0,0,0,0,0,0,0,4,0,0
0,4,0,0,0,0,0,0,0,0,0,4,0,0
0,4,0,0,0,0,0,0,0,0,0,4,0,0
0,4,4,4,4,0,0,0,4,4,4,4,0,0
0,0,0,0,0,0,0,0,0,0,0,0,0,0
endlayer

layer
0,0,0,0,0,0,0,0,0,0,0,0,0,0
0,0,0,0,0,0,0,0,0,0,0,0,0,0
0,4,4,4,4,4,4,4,4,4,4,4,0,0
0,4,4,4,4,4,4,4,4,4,4,4,0,0
0,4,4,4,4,4,4,4,4,4,4,4,0,0
0,4,4,4,4,4,4,4,4,4,4,4,0,0
0,4,4,4,4,4,4,4,4,4,4,4,0,0
0,4,4,4,4,4,4,4,4,4,4,4,0,0
0,4,4,4,4,4,4,4,4,4,4,4,0,0
0,4,4,4,4,4,4,4,4,4,4,4,0,0
0,4,4,4,4,4,4,4,4,4,4,4,0,0
0,4,4,4,4,4,4,4,4,4,4,4,0,0
0,4,4,4,4,4,4,4,4,4,4,4,0,0
0,4,4,4,4,4,4,4,4,4,4,4,0,0
0,4,4,4,4,4,4,4,4,4,4,4,0,0
0,4,4,4,4,4,4,4,4,4,4,4,0,0
0,4,4,4,4,4,4,4,4,4,4,4,0,0
0,0,0,0,0,0,0,0,0,0,0,0,0,0
endlayer

layer
0,0,0,0,0,0,0,0,0,0,0,0,0,0
0,0,0,0,0,0,0,0,0,0,0,0,0,0
0,0,0,0,0,0,0,0,0,0,0,0,0,0
0,0,4,4,4,4,4,4,4,4,4,0,0,0
0,0,4,4,4,4,4,4,4,4,4,0,0,0
0,0,4,4,4,4,4,4,4,4,4,0,0,0
0,0,4,4,4,4,4,4,4,4,4,0,0,0
0,0,4,4,4,4,4,4,4,4,4,0,0,0
0,0,4,4,4,4,4,4,4,4,4,0,0,0
0,0,4,4,4,4,4,4,4,4,4,0,0,0
0,0,4,4,4,4,4,4,4,4,4,0,0,0
0,0,4,4,4,4,4,4,4,4,4,0,0,0
0,0,4,4,4,4,4,4,4,4,4,0,0,0
0,0,4,4,4,4,4,4,4,4,4,0,0,0
0,0,4,4,4,4,4,4,4,4,4,0,0,0
0,0,4,4,4,4,4,4,4,4,4,0,0,0
0,0,0,0,0,0,0,0,0,0,0,0,0,0
0,0,0,0,0,0,0,0,0,0,0,0,0,0
endlayer

