# Título: House 1 (Plains)
# Categoria: Ruínas
# Tamanho: Médio
# Autor: Denneran
# Convertido por: Vico
# MODs Necessários: IronChest

biomesToSpawnIn=Plains,Plains M,Sunflower Plains
weight=7
embed_into_distance=1
unacceptable_target_blocks=flowing_water,water,flowing_lava,lava
dimensions=5,18,18
allowable_overhang=0
max_leveling=2
leveling_buffer=0
preserve_water=1
preserve_lava=1

rule1=0,100,preserveBlock
rule2=0,100,preserveBlock
rule3=0,90,minecraft:stonebrick-0,minecraft:stonebrick-1,minecraft:stonebrick-2,minecraft:stonebrick-0,minecraft:stonebrick-1,minecraft:stonebrick-2,minecraft:monster_egg-2,minecraft:monster_egg-3,minecraft:monster_egg-4
rule4=1,40,minecraft:tallgrass-1,minecraft:tallgrass-2,minecraft:tallgrass-1,minecraft:tallgrass-2,minecraft:yellow_flower,minecraft:red_flower,minecraft:red_flower-8
rule5=1,30,minecraft:tallgrass-1,minecraft:tallgrass-2,minecraft:tallgrass-1,minecraft:tallgrass-2,minecraft:yellow_flower,minecraft:red_flower,minecraft:red_flower-8
rule6=1,50,minecraft:tallgrass-1,minecraft:tallgrass-2,minecraft:tallgrass-1,minecraft:tallgrass-2,minecraft:yellow_flower,minecraft:red_flower,minecraft:red_flower-8
rule7=0,85,minecraft:crafting_table
rule8=0,60,IInventory;minecraft:furnace;minecraft:porkchop#8#0#0+minecraft:coal#16#0#1-3,IInventory;minecraft:furnace;minecraft:chicken#8#0#0+minecraft:coal#22#0#1-3,IInventory;minecraft:furnace;minecraft:iron_ore#8#0#0+minecraft:lava_bucket#1#0#1-3
rule9=0,65,minecraft:stone_slab-5
rule10=0,70,IInventory;ironchest:BlockIronChest;ChestGenHook:chests/spawn_bonus_chest:15,IInventory;ironchest:BlockIronChest;ChestGenHook:chests/jungle_temple:25,IInventory;ironchest:BlockIronChest;ChestGenHook:chests/village_blacksmith:50
rule11=0,70,IInventory;ironchest:BlockIronChest;ChestGenHook:chests/jungle_temple:32,IInventory;ironchest:BlockIronChest;ChestGenHook:chests/stronghold_corridor:16
rule12=0,80,minecraft:anvil-0,minecraft:anvil-1,minecraft:anvil-1,minecraft:anvil-2,minecraft:anvil-2,minecraft:anvil-2
rule13=0,70,IInventory;ironchest:BlockIronChest;ChestGenHook:chests/nether_bridge:24,IInventory;ironchest:BlockIronChest;ChestGenHook:chests/jungle_temple:32,IInventory;ironchest:BlockIronChest;ChestGenHook:chests/spawn_bonus_chest:8
rule14=0,70,IInventory;ironchest:BlockIronChest;ChestGenHook:chests/simple_dungeon:24,IInventory;ironchest:BlockIronChest;ChestGenHook:chests/jungle_temple:32,IInventory;ironchest:BlockIronChest;ChestGenHook:chests/spawn_bonus_chest:8
rule15=0,50,minecraft:stained_glass_pane,minecraft:stained_glass_pane,minecraft:stained_glass_pane-7,minecraft:stained_glass_pane-8,minecraft:stained_glass_pane-8,minecraft:stained_glass_pane-14
rule16=1,80,minecraft:hopper
rule17=1,50,ironchest:BlockIronChest
rule18=1,50,ironchest:BlockIronChest
rule19=1,50,ironchest:BlockIronChest

layer
2,2,2,2,2,2,2,2,2,2,2,2,2,2,2,2,2,1
2,2,2,2,2,2,2,2,2,2,2,2,2,2,2,2,2,2
2,2,2,2,2,2,2,2,2,2,2,2,2,2,2,2,2,2
2,2,2,2,2,2,2,2,2,2,2,2,2,2,2,2,2,2
2,2,2,1,1,1,1,3,3,1,1,1,1,2,2,2,2,2
2,2,2,1,3,3,3,2,2,2,2,2,1,2,2,2,2,2
2,2,2,1,3,3,2,2,3,1,2,1,1,2,2,2,2,2
2,2,2,1,1,2,2,3,2,2,2,2,1,2,2,2,2,2
2,2,2,3,1,3,2,3,3,2,2,1,3,2,2,2,2,2
2,2,2,3,2,3,2,3,2,2,2,2,1,2,2,2,2,2
2,2,2,1,1,3,2,3,3,2,3,1,1,2,2,2,2,2
2,2,2,1,1,2,2,2,2,2,2,2,1,2,2,2,2,2
2,2,2,1,1,1,1,1,1,1,1,1,1,2,2,2,2,2
2,2,2,2,2,2,2,2,2,2,2,2,2,2,2,2,2,2
2,2,2,2,2,2,2,2,2,2,2,2,2,2,2,2,2,2
2,2,2,2,2,2,2,2,2,2,2,2,2,2,2,2,2,2
2,2,2,2,2,2,2,2,2,2,2,2,2,2,2,2,2,2
2,2,2,2,2,2,2,2,2,2,2,2,2,2,2,2,2,2
endlayer

layer
4,4,4,4,4,4,4,4,4,4,4,4,4,4,4,4,4,1
4,4,4,4,4,5,5,5,4,4,5,4,4,5,4,4,4,4
4,5,5,6,4,5,6,4,4,5,6,6,4,4,4,4,4,4
4,4,4,4,5,6,4,4,5,4,4,4,4,5,5,4,4,4
5,5,6,3,3,3,3,0,0,3,3,3,3,4,4,6,4,4
4,5,4,3,7,0,0,5,5,5,5,5,3,4,5,4,5,4
4,4,5,3,9,0,5,5,0,3,4,8,3,4,6,4,5,4
5,6,4,3,10,9,5,0,5,5,5,5,3,4,5,5,4,4
4,5,4,3,11,0,5,0,0,4,5,8,3,4,4,4,5,4
6,4,4,3,12,0,5,0,9,5,9,5,3,4,4,5,6,4
5,5,4,3,13,3,5,0,0,5,0,8,3,4,6,5,4,4
5,6,5,3,14,5,5,5,5,5,5,5,3,4,4,4,5,4
4,5,4,3,3,3,3,3,3,3,3,3,3,4,5,5,4,4
4,5,4,5,4,4,5,4,4,4,5,4,5,4,6,4,5,4
5,4,5,6,4,4,5,4,4,6,5,4,5,4,5,4,4,4
5,4,4,5,4,5,4,5,4,4,4,6,5,4,4,4,4,4
4,4,4,5,4,5,4,6,5,4,4,4,4,4,4,4,4,4
4,4,4,4,4,4,4,4,4,4,4,4,4,4,4,4,4,4
endlayer

layer
0,0,0,0,0,0,0,0,0,0,0,0,0,0,0,0,0,1
0,0,0,0,0,0,0,0,0,0,0,0,0,0,0,0,0,0
0,0,0,0,0,0,0,0,0,0,0,0,0,0,0,0,0,0
0,0,0,0,0,0,0,0,0,0,0,0,0,0,0,0,0,0
0,0,0,3,15,3,3,0,0,3,0,3,3,0,0,0,0,0
0,0,0,15,0,0,0,0,0,0,0,0,15,0,0,0,0,0
0,0,0,3,0,0,0,0,0,0,0,16,3,0,0,0,0,0
0,0,0,0,0,0,0,0,0,0,0,0,15,0,0,0,0,0
0,0,0,15,0,0,0,0,0,0,0,16,3,0,0,0,0,0
0,0,0,3,0,0,0,0,0,0,0,0,15,0,0,0,0,0
0,0,0,15,0,0,0,0,0,0,0,16,3,0,0,0,0,0
0,0,0,0,0,0,0,0,0,0,0,0,15,0,0,0,0,0
0,0,0,3,3,0,0,3,3,9,9,3,3,0,0,0,0,0
0,0,0,0,0,0,0,0,0,0,0,0,0,0,0,0,0,0
0,0,0,0,0,0,0,0,0,0,0,0,0,0,0,0,0,0
0,0,0,0,0,0,0,0,0,0,0,0,0,0,0,0,0,0
0,0,0,0,0,0,0,0,0,0,0,0,0,0,0,0,0,0
0,0,0,0,0,0,0,0,0,0,0,0,0,0,0,0,0,0
endlayer

layer
0,0,0,0,0,0,0,0,0,0,0,0,0,0,0,0,0,1
0,0,0,0,0,0,0,0,0,0,0,0,0,0,0,0,0,0
0,0,0,0,0,0,0,0,0,0,0,0,0,0,0,0,0,0
0,0,0,0,0,0,0,0,0,0,0,0,0,0,0,0,0,0
0,0,0,3,15,0,3,0,3,3,0,3,3,0,0,0,0,0
0,0,0,15,0,0,0,0,0,0,0,0,3,0,0,0,0,0
0,0,0,3,0,0,0,0,0,0,0,17,3,0,0,0,0,0
0,0,0,3,0,0,0,0,0,0,0,0,15,0,0,0,0,0
0,0,0,15,0,0,0,0,0,0,0,18,3,0,0,0,0,0
0,0,0,3,0,0,0,0,0,0,0,0,15,0,0,0,0,0
0,0,0,15,0,0,0,0,0,0,0,19,3,0,0,0,0,0
0,0,0,0,0,0,0,0,0,0,0,0,15,0,0,0,0,0
0,0,0,3,0,0,0,3,0,0,0,3,3,0,0,0,0,0
0,0,0,0,0,0,0,0,0,0,0,0,0,0,0,0,0,0
0,0,0,0,0,0,0,0,0,0,0,0,0,0,0,0,0,0
0,0,0,0,0,0,0,0,0,0,0,0,0,0,0,0,0,0
0,0,0,0,0,0,0,0,0,0,0,0,0,0,0,0,0,0
0,0,0,0,0,0,0,0,0,0,0,0,0,0,0,0,0,0
endlayer

layer
0,0,0,0,0,0,0,0,0,0,0,0,0,0,0,0,0,2
0,0,0,0,0,0,0,0,0,0,0,0,0,0,0,0,0,0
0,0,0,0,0,0,0,0,0,0,0,0,0,0,0,0,0,0
0,0,0,0,0,0,0,0,0,0,0,0,0,0,0,0,0,0
0,0,0,3,3,3,3,3,3,0,3,3,3,0,0,0,0,0
0,0,0,3,3,3,3,3,0,3,3,3,3,0,0,0,0,0
0,0,0,0,3,3,3,0,0,3,3,3,0,0,0,0,0,0
0,0,0,3,3,3,0,0,0,0,3,3,0,0,0,0,0,0
0,0,0,3,3,3,0,0,0,0,0,3,0,0,0,0,0,0
0,0,0,3,3,0,0,0,0,0,0,0,3,0,0,0,0,0
0,0,0,3,0,0,0,0,0,0,0,0,3,0,0,0,0,0
0,0,0,0,0,0,0,0,0,3,3,3,3,0,0,0,0,0
0,0,0,0,0,0,3,3,0,0,3,3,3,0,0,0,0,0
0,0,0,0,0,0,0,0,0,0,0,0,0,0,0,0,0,0
0,0,0,0,0,0,0,0,0,0,0,0,0,0,0,0,0,0
0,0,0,0,0,0,0,0,0,0,0,0,0,0,0,0,0,0
0,0,0,0,0,0,0,0,0,0,0,0,0,0,0,0,0,0
0,0,0,0,0,0,0,0,0,0,0,0,0,0,0,0,0,0
endlayer

