# Título: Gateway (Deserto)
# Categoria: Ruínas
# Tamanho: Médio
# Autor: Denneran
# Convertido por: Vico

biomesToSpawnIn=Desert,Desert M,Beach
weight=10
embed_into_distance=1
acceptable_target_blocks=sand,sandstone
unacceptable_target_blocks=flowing_water,water,flowing_lava,lava
dimensions=5,30,18
allowable_overhang=0
max_leveling=2
leveling_buffer=0
preserve_water=1
preserve_lava=1

rule1=0,100,preserveBlock
rule2=0,80,minecraft:sandstone,preserveBlock
rule3=0,90,minecraft:sandstone-1,minecraft:sandstone-2
rule4=0,50,minecraft:web

layer
1,1,1,1,1,1,1,1,2,2,1,1,1,1,1,1,1,1
1,1,1,1,1,1,1,1,2,2,1,1,1,1,1,1,1,1
1,1,1,1,1,1,1,1,2,2,1,1,1,1,1,1,1,1
1,1,1,1,1,1,1,1,2,2,1,1,1,1,1,1,1,1
1,1,1,1,1,1,1,1,2,2,1,1,1,1,1,1,1,1
1,1,1,1,1,1,1,1,2,2,1,1,1,1,1,1,1,1
1,1,1,1,1,1,1,1,2,2,1,1,1,1,1,1,1,1
1,1,1,1,1,1,1,1,2,2,1,1,1,1,1,1,1,1
1,1,1,1,1,1,1,1,2,2,1,1,1,1,1,1,1,1
1,1,1,1,1,1,1,1,2,2,1,1,1,1,1,1,1,1
1,1,1,1,1,1,1,1,2,2,1,1,1,1,1,1,1,1
1,1,1,1,1,1,1,1,2,2,1,1,1,1,1,1,1,1
1,1,1,1,1,1,1,1,2,2,1,1,1,3,3,1,1,1
1,1,3,1,1,1,1,1,2,2,1,1,1,1,1,1,1,1
1,1,1,1,1,1,1,1,2,2,1,1,1,1,1,1,1,1
1,1,1,1,3,1,1,1,2,2,1,1,1,1,1,1,1,1
1,1,1,1,3,1,1,1,2,2,1,1,1,1,3,1,1,1
1,1,1,1,1,1,1,1,2,2,1,1,1,1,1,1,1,1
1,1,1,1,1,1,1,1,2,2,1,1,1,1,1,1,1,1
1,1,1,1,1,1,1,1,2,2,1,1,1,1,1,1,1,1
1,1,1,1,1,1,1,1,2,2,1,1,1,1,1,1,1,1
1,1,1,1,1,1,1,1,2,2,1,1,1,1,1,1,1,1
1,1,1,1,1,1,1,1,2,2,1,1,1,1,1,1,1,1
1,1,1,1,1,1,1,1,2,2,1,1,1,1,1,1,1,1
1,1,1,1,1,1,1,1,2,2,1,1,1,1,1,1,1,1
1,1,1,1,1,1,1,1,2,2,1,1,1,1,1,1,1,1
1,1,1,1,1,1,1,1,2,2,1,1,1,1,1,1,1,1
1,1,1,1,1,1,1,1,2,2,1,1,1,1,1,1,1,1
1,1,1,1,1,1,1,1,2,2,1,1,1,1,1,1,1,1
1,1,1,1,1,1,1,1,2,2,1,1,1,1,1,1,1,1
endlayer

layer
0,0,0,0,0,0,0,0,0,0,0,0,0,0,0,0,0,0
0,0,0,0,0,0,0,0,0,0,0,0,0,0,0,0,0,0
0,0,0,0,0,0,0,0,0,0,0,0,0,0,0,0,0,0
0,0,0,0,0,0,0,0,0,0,0,0,0,0,0,0,0,0
0,0,0,0,0,0,0,0,0,0,0,0,0,0,0,0,0,0
0,0,0,0,0,0,0,0,0,0,0,0,0,0,0,0,0,0
0,0,0,0,0,0,0,0,0,0,0,0,0,0,0,0,0,0
0,0,0,0,0,0,0,0,0,0,0,0,0,0,0,0,0,0
0,0,0,0,0,0,0,0,0,0,0,0,0,0,0,0,0,0
0,0,0,0,0,0,0,0,0,0,0,0,0,0,0,0,0,0
0,0,0,0,0,0,0,0,0,0,0,0,0,0,0,0,0,0
0,0,0,0,0,0,0,0,0,0,0,0,0,0,0,0,0,0
0,4,3,3,3,3,3,0,0,0,0,3,3,0,0,3,3,0
0,3,0,3,3,3,3,0,0,0,0,3,3,3,3,3,3,0
0,0,3,3,3,3,3,0,0,0,0,3,0,0,0,3,3,0
0,0,3,3,0,3,3,0,0,0,0,3,3,3,3,3,3,0
0,0,0,0,0,0,0,0,0,0,0,0,0,0,0,3,0,0
0,0,0,0,0,0,0,0,0,0,0,0,0,0,0,0,0,0
0,0,0,0,0,0,0,0,0,0,0,0,0,0,0,0,0,0
0,0,0,0,0,0,0,0,0,0,0,0,0,0,0,0,0,0
0,0,0,0,0,0,0,0,0,0,0,0,0,0,0,0,0,0
0,0,0,0,0,0,0,0,0,0,0,0,0,0,0,0,0,0
0,0,0,0,0,0,0,0,0,0,0,0,0,0,0,0,0,0
0,0,0,0,0,0,0,0,0,0,0,0,0,0,0,0,0,0
0,0,0,0,0,0,0,0,0,0,0,0,0,0,0,0,0,0
0,0,0,0,0,0,0,0,0,0,0,0,0,0,0,0,0,0
0,0,0,0,0,0,0,0,0,0,0,0,0,0,0,0,0,0
0,0,0,0,0,0,0,0,0,0,0,0,0,0,0,0,0,0
0,0,0,0,0,0,0,0,0,0,0,0,0,0,0,0,0,0
0,0,0,0,0,0,0,0,0,0,0,0,0,0,0,0,0,0
endlayer

layer
0,0,0,0,0,0,0,0,0,0,0,0,0,0,0,0,0,0
0,0,0,0,0,0,0,0,0,0,0,0,0,0,0,0,0,0
0,0,0,0,0,0,0,0,0,0,0,0,0,0,0,0,0,0
0,0,0,0,0,0,0,0,0,0,0,0,0,0,0,0,0,0
0,0,0,0,0,0,0,0,0,0,0,0,0,0,0,0,0,0
0,0,0,0,0,0,0,0,0,0,0,0,0,0,0,0,0,0
0,0,0,0,0,0,0,0,0,0,0,0,0,0,0,0,0,0
0,0,0,0,0,0,0,0,0,0,0,0,0,0,0,0,0,0
0,0,0,0,0,0,0,0,0,0,0,0,0,0,0,0,0,0
0,0,0,0,0,0,0,0,0,0,0,0,0,0,0,0,0,0
0,0,0,0,0,0,0,0,0,0,0,0,0,0,0,0,0,0
0,0,0,0,0,0,0,0,0,0,0,0,0,0,0,0,0,0
0,0,0,3,0,3,3,0,0,0,0,3,3,3,3,3,0,0
0,0,0,0,3,0,3,0,0,0,0,3,3,3,3,0,3,0
0,0,0,0,0,3,3,0,0,0,0,3,3,3,3,0,3,0
0,0,0,3,3,3,3,0,0,0,0,3,3,3,0,3,3,0
0,0,0,0,0,0,0,0,0,0,0,0,0,0,0,0,0,0
0,0,0,0,0,0,0,0,0,0,0,0,0,0,0,0,0,0
0,0,0,0,0,0,0,0,0,0,0,0,0,0,0,0,0,0
0,0,0,0,0,0,0,0,0,0,0,0,0,0,0,0,0,0
0,0,0,0,0,0,0,0,0,0,0,0,0,0,0,0,0,0
0,0,0,0,0,0,0,0,0,0,0,0,0,0,0,0,0,0
0,0,0,0,0,0,0,0,0,0,0,0,0,0,0,0,0,0
0,0,0,0,0,0,0,0,0,0,0,0,0,0,0,0,0,0
0,0,0,0,0,0,0,0,0,0,0,0,0,0,0,0,0,0
0,0,0,0,0,0,0,0,0,0,0,0,0,0,0,0,0,0
0,0,0,0,0,0,0,0,0,0,0,0,0,0,0,0,0,0
0,0,0,0,0,0,0,0,0,0,0,0,0,0,0,0,0,0
0,0,0,0,0,0,0,0,0,0,0,0,0,0,0,0,0,0
0,0,0,0,0,0,0,0,0,0,0,0,0,0,0,0,0,0
endlayer

layer
0,0,0,0,0,0,0,0,0,0,0,0,0,0,0,0,0,0
0,0,0,0,0,0,0,0,0,0,0,0,0,0,0,0,0,0
0,0,0,0,0,0,0,0,0,0,0,0,0,0,0,0,0,0
0,0,0,0,0,0,0,0,0,0,0,0,0,0,0,0,0,0
0,0,0,0,0,0,0,0,0,0,0,0,0,0,0,0,0,0
0,0,0,0,0,0,0,0,0,0,0,0,0,0,0,0,0,0
0,0,0,0,0,0,0,0,0,0,0,0,0,0,0,0,0,0
0,0,0,0,0,0,0,0,0,0,0,0,0,0,0,0,0,0
0,0,0,0,0,0,0,0,0,0,0,0,0,0,0,0,0,0
0,0,0,0,0,0,0,0,0,0,0,0,0,0,0,0,0,0
0,0,0,0,0,0,0,0,0,0,0,0,0,0,0,0,0,0
0,0,0,0,0,0,0,0,0,0,0,0,0,0,0,0,0,0
0,0,0,3,3,3,3,3,0,0,3,3,3,0,0,0,0,0
0,0,0,0,0,3,3,3,0,0,3,3,0,0,0,0,3,0
0,0,0,0,3,3,3,3,0,0,3,3,0,0,3,3,3,0
0,0,0,0,3,0,3,3,0,0,3,3,3,3,3,0,3,0
0,0,0,0,0,0,0,0,0,0,0,0,0,0,0,0,0,0
0,0,0,0,0,0,0,0,0,0,0,0,0,0,0,0,0,0
0,0,0,0,0,0,0,0,0,0,0,0,0,0,0,0,0,0
0,0,0,0,0,0,0,0,0,0,0,0,0,0,0,0,0,0
0,0,0,0,0,0,0,0,0,0,0,0,0,0,0,0,0,0
0,0,0,0,0,0,0,0,0,0,0,0,0,0,0,0,0,0
0,0,0,0,0,0,0,0,0,0,0,0,0,0,0,0,0,0
0,0,0,0,0,0,0,0,0,0,0,0,0,0,0,0,0,0
0,0,0,0,0,0,0,0,0,0,0,0,0,0,0,0,0,0
0,0,0,0,0,0,0,0,0,0,0,0,0,0,0,0,0,0
0,0,0,0,0,0,0,0,0,0,0,0,0,0,0,0,0,0
0,0,0,0,0,0,0,0,0,0,0,0,0,0,0,0,0,0
0,0,0,0,0,0,0,0,0,0,0,0,0,0,0,0,0,0
0,0,0,0,0,0,0,0,0,0,0,0,0,0,0,0,0,0
endlayer

layer
0,0,0,0,0,0,0,0,0,0,0,0,0,0,0,0,0,0
0,0,0,0,0,0,0,0,0,0,0,0,0,0,0,0,0,0
0,0,0,0,0,0,0,0,0,0,0,0,0,0,0,0,0,0
0,0,0,0,0,0,0,0,0,0,0,0,0,0,0,0,0,0
0,0,0,0,0,0,0,0,0,0,0,0,0,0,0,0,0,0
0,0,0,0,0,0,0,0,0,0,0,0,0,0,0,0,0,0
0,0,0,0,0,0,0,0,0,0,0,0,0,0,0,0,0,0
0,0,0,0,0,0,0,0,0,0,0,0,0,0,0,0,0,0
0,0,0,0,0,0,0,0,0,0,0,0,0,0,0,0,0,0
0,0,0,0,0,0,0,0,0,0,0,0,0,0,0,0,0,0
0,0,0,0,0,0,0,0,0,0,0,0,0,0,0,0,0,0
0,0,0,0,0,0,0,0,0,0,0,0,0,0,0,0,0,0
0,0,0,0,0,0,3,3,0,3,3,0,0,0,0,0,0,0
0,0,0,0,0,0,0,3,3,3,3,0,0,0,0,0,0,0
0,0,0,0,0,0,3,3,3,0,3,0,0,0,0,0,0,0
0,0,0,0,3,3,3,3,0,3,3,0,0,0,3,3,3,0
0,0,0,0,0,0,0,0,0,0,0,0,0,0,0,0,0,0
0,0,0,0,0,0,0,0,0,0,0,0,0,0,0,0,0,0
0,0,0,0,0,0,0,0,0,0,0,0,0,0,0,0,0,0
0,0,0,0,0,0,0,0,0,0,0,0,0,0,0,0,0,0
0,0,0,0,0,0,0,0,0,0,0,0,0,0,0,0,0,0
0,0,0,0,0,0,0,0,0,0,0,0,0,0,0,0,0,0
0,0,0,0,0,0,0,0,0,0,0,0,0,0,0,0,0,0
0,0,0,0,0,0,0,0,0,0,0,0,0,0,0,0,0,0
0,0,0,0,0,0,0,0,0,0,0,0,0,0,0,0,0,0
0,0,0,0,0,0,0,0,0,0,0,0,0,0,0,0,0,0
0,0,0,0,0,0,0,0,0,0,0,0,0,0,0,0,0,0
0,0,0,0,0,0,0,0,0,0,0,0,0,0,0,0,0,0
0,0,0,0,0,0,0,0,0,0,0,0,0,0,0,0,0,0
0,0,0,0,0,0,0,0,0,0,0,0,0,0,0,0,0,0
endlayer

